Workbook

Sheet תוכניות בינוי
A1: מס׳ תיק | B1: מס׳ תכנית | C1: רובע | D1: מיקום / מגרש | E1: שם הפרויקט | F1: תב״ע חלה | G1: ייעוד | H1: גוש / חלקה | I1: יזם | J1: טלפון יזם | K1: מייל יזם | L1: אדריכל / מגיש | M1: טלפון אדריכל | N1: מייל אדריכל | O1: איש קשר | P1: טלפון איש קשר | Q1: תאריך פתיחה | R1: תאריך ועדה | S1: מס׳ ישיבה | T1: החלטת ועדה | U1: סטטוס | V1: מטפלת | W1: הקלות מבוקשות | X1: הערות לבדיקה
A2: 1747 | B2: תב/1743 | C2: מיוחד | D2: מגרש מתחם י"א הרובע המיוחד | F2: 603-0811588 | L2: אד' הדס אדריכלות ועיצוב בעמ | Q2: 45225 | U2: הושלם | V2: ענת שטיבלמן | X2: מס׳ התיק שונה ממס׳ התכנית
A3: 1749 | B3: תב/1745 | C3: מיוחד | D3: מגרשים 602-605 | F3: 603-0811588 | L3: אד' גנאדי טרוינין | Q3: 45236 | U3: הושלם | V3: ענת שטיבלמן | X3: מס׳ התיק שונה ממס׳ התכנית
A4: 1753 | B4: תב/1739 | C4: ט"ז | D4: מגרש מנגו 4 | F4: 603-03117784 | L4: אד' גנאדי טרוינין | Q4: 45267 | U4: הושלם | V4: ענת שטיבלמן | X4: מס׳ התיק שונה ממס׳ התכנית
A5: 1754 | B5: תב/1736 | C5: חוף הים | D5: מגרש חוף הים | F5: 44/101/02/3 | L5: אד' יואל פייגין | Q5: 45270 | U5: הושלם | V5: ענת שטיבלמן | X5: מס׳ התיק שונה ממס׳ התכנית; מס׳ תיק כפול
A6: 1732 | B6: תב/1732 | C6: מרינה | D6: מגרש מרינה | E6: תוכנית בינוי - תב/1732 - מגרשים 46,51 - יזם: אסטנג'לוב | F6: 112/101/02/3 | G6: מסחר ומלון (מגרש 46), מגורים (מגרש 51) | H6: גוש 2791 חלקות 62-86 | I6: אסטנג'לוב השקעות בע"מ | L6: דני רוזן | Q6: 45427 | R6: 45434 | S6: 202402 | T6: לאשר את תכנית הבינוי בכפוף לתיקונים | U6: הושלם | V6: ענת שטיבלמן | W6: הקלות בקווי בניין לבריכות; מרחק בין בנייני מגורים 11.25-13.75 במקום 20 מ'; הנמכת מפלס 0.00 והחניון; המרת וניוד שטחי שירות למלונאות ומסחר; חדר יציאה ופרגולה לגג המלון; הקטנת שטח חלחול מ-30% ל-12%; זיקות הנאה.
A7: 1778 | B7: תב/1750 | C7: פארק לכיש | D7: מגרש פארק לכיש מגרשים 27,29,32 | F7: תמל 1062 | L7: אד' טטרו שחר אדריכלים | Q7: 45544 | U7: הושלם | V7: ענת שטיבלמן | X7: מס׳ התיק שונה ממס׳ התכנית
A8: 1800 | B8: תב/1800 | C8: מיוחד | D8: מגרש 625-626 | E8: תוכנית בינוי - תב/1800 / רובע מיוחד - מגרשים 625-626 | F8: 603-0811588 | G8: מגורים בלבד | H8: גוש 181 חלקות 10, 11, 16, 24, 64 | I8: האחים ישראל בע"מ | J8: 02-6245552 | K8: office@israelbrothers.co.il | L8: עמית וינברג | M8: 054-6435646 | N8: amitw.arch@gmail.com | O8: הראל קאפח | P8: 052-8389616 | Q8: 45593 | R8: 45650 | S8: 202411 | T8: לאשר את תכנית הבינוי | U8: הושלם | V8: ענת שטיבלמן | W8: הקלות: ניוד, תכסית, נסיגות, תקן חנייה; תקן חניה 1:1.5 לכלל הדירות; הקלה לחניות אורחים מ-20% ל-10%; הקלה למיקום המחסנים.
A9: 1811 | B9: תב/1811 | C9: מיוחד | D9: מגרש 601 | E9: תב/1811 תוכנית בינוי - מגרש 601 - יזם: יצחק אטיאס | F9: 603-0811588 | G9: מגורים ד' | H9: גוש 2022 חלקה 7 | I9: יצחק אטיאס חברה לבנייה בע"מ (איש קשר: דודו אטיאס) | J9: 0537395569 | K9: dudu@atias.co.il | L9: דאובר אדריכלים | M9: 035227717 | N9: galz@dauber-arch.co.il | Q9: 45594 | R9: 45790 | S9: 202507 | T9: לאשר את תכנית הבינוי | U9: הושלם | V9: ענת שטיבלמן
A10: 1807 | B10: תב/1815 | C10: מרינה | D10: מגרש 50,45 | E10: תוכנית בינוי - תב/1815 - מרינה - יחד הבונים ייזום ובנייה בע"מ | F10: 112/101/02/3 | H10: גוש 2791 חלקה 63 | I10: יחד הבונים ייזום ובנייה בע"מ | J10: 08-8530996 | K10: yachad@y-hb.co.il | L10: מוטי בניטה | M10: 054-4291705 | N10: studiomotib@gmail.com | O10: אלי רוז | P10: 0544250681 | Q10: 45615 | R10: 45678 | S10: 202502 | T10: לאשר את תכנית הבינוי | U10: הושלם | V10: ענת שטיבלמן | W10: הקלה ליציאה לגג המלון עם בריכה; ניוד שטחים עיקריים; הנמכת 0.00 כ-2.05; ברכות פרטיות לדירות גן וגג (כ-18); הקלה לקו בניין קדמי ואחורי לבליטת מרפסות; הקלה לחניה מתקן מקומי לארצי | X10: מס׳ התיק שונה ממס׳ התכנית
A11: 1808 | B11: תב/1816 | C11: מרינה | D11: מגרש 52,47 | F11: 112/101/02/3 | L11: אד' אפי | Q11: 45616 | U11: הושלם | V11: ענת שטיבלמן | X11: מס׳ התיק שונה ממס׳ התכנית
A12: 1809 | B12: תב/1824 | C12: סיטי | D12: מגרש 141 | F12: 603-0735282 | L12: אד' דוד שבזין | Q12: 45617 | U12: הושלם | V12: ענת שטיבלמן | X12: מס׳ התיק שונה ממס׳ התכנית
A13: 1810 | B13: תב/1713 | C13: מיוחד | D13: מגרש 618 | F13: 603-0811588 | L13: אד' טיטו אומן | Q13: 45617 | U13: הושלם | V13: ענת שטיבלמן | X13: מס׳ התיק שונה ממס׳ התכנית
A14: 1714 | B14: תב/1714 | C14: טו' | D14: מגרש 18 | E14: ריבירה - מגרש 18 מגורים ומלונאות | F14: 603-0262121 | G14: מלונאות, מגורים ומסחר | H14: גוש 2649 חלקה 5 | I14: אבו יחיאל חברה לבניין בע"מ | J14: 054-2609503 | K14: office@abultd.com | L14: יואל פייגין | M14: 03-6791000 | N14: feigin@feiginarch.co.il | O14: מוטי אסולין | P14: 053-4210422 | Q14: 45622 | R14: 45629 | S14: 202410 | T14: לאשר את תכנית הבינוי | U14: הושלם | V14: ענת שטיבלמן | W14: הקלה בתקן חנייה למגורים (מיחס 1:1 לדירות קטנות ליחס 1:0.75) להשלמת כ-43 מקומות חנייה; נושא ההקלות יעודכן וייבחן בהליך הרישוי.
A15: 1754 | B15: תב/1730 | C15: סיטי | D15: מגרש 142 | F15: 603-0735282 | L15: אד' דוד | Q15: 45628 | U15: הושלם | V15: ענת שטיבלמן | X15: מס׳ התיק שונה ממס׳ התכנית; מס׳ תיק כפול
A16: 1815 | B16: תב/1735 | C16: מיוחד | D16: מגרש 619 | F16: 603-0811588 | L16: אד' אליעזר | Q16: 45628 | U16: הושלם | V16: ענת שטיבלמן | X16: מס׳ התיק שונה ממס׳ התכנית
A17: 1844 | B17: תב/1844 | C17: פארק לכיש | D17: מגרש 502 - פארק לכיש | E17: תוכנית בינוי - תב/1844 - מגרש 502 - יזם גל יוזמה | F17: תמל 1062 | G17: מסחר ותעסוקה | H17: גוש 2062 חלקה 122 | I17: גל יוזמה מרכזי מסחר בע"מ | L17: גיא גולדשטיין, גיא אדריכלים | Q17: 45774 | R17: 45790 | S17: 202507 | T17: לאשר את תכנית הבינוי | U17: הושלם | V17: ענת שטיבלמן
A18: 1845 | B18: תב/1845 | C18: מע"ר דרום | D18: מגרש 106,33 | E18: תוכנית בינוי - תב/1845 - מגרשים 33,106 - יזם חיים רוקח | F18: 603-0477232 | G18: מגורים; מסחר ותעסוקה | H18: גוש 3174 חלקה 3 | I18: רוקח חברה לבניה בע"מ | L18: הרן ילין אדריכלות ובינוי ערים | Q18: 45774 | R18: 45790 | S18: 202507 | T18: לאשר את תכנית הבינוי המוצעת בכפוף לתנאים המפורטים בהערות הבדיקה | U18: הושלם | V18: ענת שטיבלמן | W18: רישום זיקות הנאה; חניה משותפת לשני המגרשים; ניהול מי נגר לשצ"פ הסמוך; חריגה בתכסית החניון התת-קרקעי ל-100% במגרש 106; חניה עילית לרכב מסחרי אחד לפריקה וטעינה
A19: 1847 | B19: תב/1847 | C19: א' | D19: מגרש 24 | F19: 603-0394320 | L19: אד' אלי זהבי | Q19: 45777 | U19: הושלם | V19: ענת שטיבלמן
A20: 1862 | B20: תב/1862 | C20: מע"ר דרום | D20: מגרש 5 | E20: תוכנית בינוי תב/1862 - מגרש 5 - יזם: אבו יחיאל - אד': גיל מיניסטר | F20: 603-0477232 | G20: מגורים | H20: גוש 3174 ח"ח 28 | I20: אבו יחיאל חברה לבנין בע"מ | J20: 052-9591310 | K20: shirel@abultd.com | L20: גיל מינסטר אדריכלים | M20: 08-9362618 | N20: office@gilminster.com | Q20: 45858 | R20: 45965 | S20: 202514 | T20: לאשר את השינויים לתכנית הבינוי | U20: הושלם | V20: ענת שטיבלמן | W20: תוספת 2 קומות ו-2 יחידות דיור (דו-קומתיות) על גג המבנה הקיים לבניין B; חדר יציאה לגג; מרפסות גג וזיז; פרגולות; בריכה לכל דירה (2 ברכות)
A21: 1863 | B21: תב/1863 | C21: מע"ר דרום | D21: מגרש 1 | F21: 603-0477232 | L21: אד' גיל מינסטר | Q21: 45866 | U21: הושלם | V21: ענת שטיבלמן
A22: 1871 | B22: תב/1871 | C22: מרינה | D22: מגרש 42,43,44 | E22: תוכנית בינוי - תב/1871 - מרינה - מגרשים 42,43,44 | F22: 112//101/02/3 | G22: מלונאות ומסחר | H22: גוש 2791 | I22: אסנג'לוב | L22: רוזן אדריכלים - דני רוזן | M22: 054-5226221 | N22: Rozen.arch@gmail.com | O22: טל שי | P22: 050-5339348 | Q22: 45914 | R22: 46098 | S22: 202605 | T22: לאשר את תכנית הבינוי | U22: הושלם | V22: ענת שטיבלמן | W22: הקלות במפלס 0.00 (מ-7.50+ ל-15.0+), מניין קומות (3 מתחת + 16 מעל), ניוד כ-600 מ"ר מתחת ל-0.00, חריגה עד 4 מ' מקו בניין קדמי, מיקום חניה בין מגרשים סמוכים, תקן חניה ארצי, ביטול קירוי מעבר
A23: 1873 | B23: תב/1873 | C23: מע"ר דרום | D23: מגרש 23 | E23: תוכנית בינוי תב/1873 - מגרש 23 | F23: 603-0477232 | H23: גוש 3174 חלקה 22 | I23: ש.ס. אדיר חברה ליזמות והשקעות בע"מ | J23: 050-4000742 (שאול אקב) | K23: Shaul.101a@gmail.com | L23: וולטר שיינקמן | M23: 050-5271069 | N23: walter@walter.co.il | Q23: 45914 | R23: 45965 | S23: 202514 | T23: לאשר את תכנית הבינוי | U23: הושלם | V23: ענת שטיבלמן
A24: 1885 | B24: תב/1885 | C24: ב' | D24: מגרש מתחם סוהו - רחוב האורגים | F24: 603-0590729 | L24: אד' לאה שניאור | Q24: 45931 | U24: הושלם | V24: ענת שטיבלמן
A25: 1876 | B25: תב/1876 | C25: מיוחד | D25: מגרש 618 | E25: תוכנית בינוי תב/1876 - מגרש 618 - שינוי לתוכנית בינוי תב/1713 | F25: 603-0811588 | G25: מגורים, תוספת שטחי מסחר | H25: גוש 2022 חלקה 7 | I25: חברת רוטשטיין | L25: יואב אומן | M25: 054-4431637 | N25: yoav@tito-oman.com | O25: מרים סולומון (חברת רוטשטיין) | P25: 054-4720940 | Q25: 45956 | R25: 45965 | S25: 202514 | T25: לאשר את תכנית הבינוי | U25: הושלם | V25: ענת שטיבלמן
A26: 1886 | B26: תב/1886 | C26: מע"ר דרום | D26: מגרש 2 | F26: 603-0477232 | L26: אד' גיל מיניסטר | Q26: 45962 | U26: הושלם | V26: ענת שטיבלמן
A27: 1887 | B27: תב/1887 | C27: ה' | D27: מגרש נאות ספיר | F27: תמל 2024 | L27: אד' יגאל לוי | Q27: 45992 | U27: הושלם | V27: ענת שטיבלמן
A28: 1888 | B28: תב/1888 | C28: ח' | D28: מגרש רותם פלדות - תדהר | F28: 603-1460740 | L28: אד' גיל מיניסטר | Q28: 45992 | U28: הושלם | V28: ענת שטיבלמן
A29: 1880 | B29: תב/1880 | C29: מע"ר דרום | D29: מגרש 11 | E29: תוכנית בינוי תב/1880 - שינוי לתוכנית בינוי קיימת - מער דרום - מגרש 11 | F29: 603-0477232 | G29: תוספת זכויות בניה ויח"ד ברובע מע"ר דרום | H29: גוש 3174 חלקה 31 | I29: אוצר בניה והשקעות בע"מ (צחי אבו) | J29: 0502761321 | K29: k0502761321@gmail.com | L29: בסאם נאסר | M29: 0504255961 | N29: arch.bn.tira@gmail.com | Q29: 46000 | R29: 46028 | S29: 202601 | T29: לאשר את תכנית הבינוי. | U29: הושלם | V29: ענת שטיבלמן
A30: 1901 | B30: תב/1901 | C30: חוף יא | D30: מגרש חוף יא | E30: פארק ספריי אשדוד — פארק משחקי מים | F30: 14/118/03/3 | G30: שטח ציבורי פתוח | H30: גוש 2791 | I30: אדיר מלכה | J30: 050-7483784 | K30: watergoal@hotmail.com | L30: אייל לוגאסי | M30: 052-3443825 | N30: eyalarch@gmail.com | Q30: 46089 | R30: 46098 | S30: 202605 | T30: לאשר את תכנית הבינוי | U30: הושלם | V30: ענת שטיבלמן
A31: 1902 | B31: תב/1902 | C31: חנ"י | D31: מגרש נמל אשדוד | F31: 47/101/02/3 | L31: אד' יבגני ברופמן | Q31: 46089 | U31: הושלם | V31: ענת שטיבלמן
A32: 1908 | B32: תב/1908 | C32: מע"ר דרום | D32: מגרש מער דרום | F32: 603-0477232 | L32: אד' אפרייט | Q32: 46180 | U32: הושלם | V32: ענת שטיבלמן
A33: 1909 | B33: תב/1909 | C33: א | D33: מגרש מתחם האצטדיון | F33: 603-1308642 | L33: אד' איגרא | Q33: 46181 | U33: טרם עודכן | V33: ענת שטיבלמן
A34: 1910 | B34: תב/1910 | C34: א | D34: מגרש מרכז א | F34: 603-0391219 | L34: אד' גיל מיניסטר | Q34: 46182 | U34: בטיפול | V34: ענת שטיבלמן | X34: בארכיון נמצא מסמך תב/1910 אחר (שינוי קווי בניין - בוזגלו 40,50 רובע ט' אשדוד, ועדה 24/02/2026) — לא שויך
A35: 1911 | B35: תב/1911 | C35: ב | D35: מגרש מתחם הרב מימון | L35: אד' גיל מיניסטר | Q35: 46183 | U35: בטיפול | V35: ענת שטיבלמן
A36: 1912 | B36: תב/1912 | C36: ב | D36: מגרש מתחם המעפילים | F36: תמל 2022 | L36: אד' גיל מיניסטר | Q36: 46184 | U36: בטיפול | V36: ענת שטיבלמן
A37: 1913 | B37: תב/1913 | C37: אחד העם | D37: מגרש ציר הרצל אחד העם | F37: תמל 2023 | L37: אד' גיל מיניסטר | Q37: 46185 | U37: בטיפול | V37: ענת שטיבלמן
A38: 1802 | B38: תב/1802 | C38: ריביירה | D38: מגרש טניס | E38: תוכנית בינוי - תב/1802 - ריביירה - מגרש 8ב - מגרשי הטניס | F38: 44/101/02/3 | G38: ספורט | H38: גוש 2002 חלקות 6, 164, 7 | I38: רשות הספורט -עיריית אשדוד | J38: 054-6764242 | L38: מידד גנדלר | M38: 052-3658752 | O38: יורם אסרף | P38: 054-6764242 | R38: 45608 | S38: 202409 | T38: לאשר את תכנית הבינוי | U38: הושלם | V38: ענת שטיבלמן | W38: התוכנית תואמת תב"ע; הקלות אם יידרשו ייבחנו בהליך הרישוי; חניה מבוקש 134 מתוך 160 (80% תפוסה). | X38: חסר תאריך פתיחה
A39: 1803 | B39: תב/1803 | C39: פארק לכיש | D39: מגרש 503 | F39: תמל 1062 | U39: הושלם | V39: ענת שטיבלמן | X39: חסר תאריך פתיחה
A40: 1804 | B40: תב/1804 | C40: פארק לכיש | D40: מגרש 504 | F40: תמל 1062 | U40: הושלם | V40: ענת שטיבלמן | X40: חסר תאריך פתיחה
...

Sheet סיכום
A1: סה״כ תוכניות | B1: =COUNTA('תוכניות בינוי'!$A$2:$A$41)
A2: עם תאריך ועדה | B2: =COUNT('תוכניות בינוי'!$R$2:$R$41)
A4: לפי סטטוס
A5: סטטוס | B5: מס׳ תוכניות
A6: בטיפול | B6: =COUNTIF('תוכניות בינוי'!$U$2:$U$41,"בטיפול")
A7: הושלם | B7: =COUNTIF('תוכניות בינוי'!$U$2:$U$41,"הושלם")
A8: טרם עודכן | B8: =COUNTIF('תוכניות בינוי'!$U$2:$U$41,"טרם עודכן")
A10: לפי שנת פתיחה
A11: שנה | B11: מס׳ תוכניות
A12: 2023 | B12: =COUNTIFS('תוכניות בינוי'!$Q$2:$Q$41,">="&DATE(2023,1,1),'תוכניות בינוי'!$Q$2:$Q$41,"<"&DATE(2024,1,1))
A13: 2024 | B13: =COUNTIFS('תוכניות בינוי'!$Q$2:$Q$41,">="&DATE(2024,1,1),'תוכניות בינוי'!$Q$2:$Q$41,"<"&DATE(2025,1,1))
A14: 2025 | B14: =COUNTIFS('תוכניות בינוי'!$Q$2:$Q$41,">="&DATE(2025,1,1),'תוכניות בינוי'!$Q$2:$Q$41,"<"&DATE(2026,1,1))
A15: 2026 | B15: =COUNTIFS('תוכניות בינוי'!$Q$2:$Q$41,">="&DATE(2026,1,1),'תוכניות בינוי'!$Q$2:$Q$41,"<"&DATE(2027,1,1))
A17: לפי רובע
A18: רובע | B18: מס׳ תוכניות
A19: א | B19: =COUNTIF('תוכניות בינוי'!$C$2:$C$41,"א")
A20: א' | B20: =COUNTIF('תוכניות בינוי'!$C$2:$C$41,"א'")
A21: אחד העם | B21: =COUNTIF('תוכניות בינוי'!$C$2:$C$41,"אחד העם")
A22: ב | B22: =COUNTIF('תוכניות בינוי'!$C$2:$C$41,"ב")
A23: ב' | B23: =COUNTIF('תוכניות בינוי'!$C$2:$C$41,"ב'")
A24: ה' | B24: =COUNTIF('תוכניות בינוי'!$C$2:$C$41,"ה'")
A25: ח' | B25: =COUNTIF('תוכניות בינוי'!$C$2:$C$41,"ח'")
A26: חוף הים | B26: =COUNTIF('תוכניות בינוי'!$C$2:$C$41,"חוף הים")
A27: חוף יא | B27: =COUNTIF('תוכניות בינוי'!$C$2:$C$41,"חוף יא")
A28: חנ"י | B28: =COUNTIF('תוכניות בינוי'!$C$2:$C$41,"חנ""י")
A29: ט"ז | B29: =COUNTIF('תוכניות בינוי'!$C$2:$C$41,"ט""ז")
A30: טו' | B30: =COUNTIF('תוכניות בינוי'!$C$2:$C$41,"טו'")
A31: מיוחד | B31: =COUNTIF('תוכניות בינוי'!$C$2:$C$41,"מיוחד")
A32: מע"ר דרום | B32: =COUNTIF('תוכניות בינוי'!$C$2:$C$41,"מע""ר דרום")
A33: מרינה | B33: =COUNTIF('תוכניות בינוי'!$C$2:$C$41,"מרינה")
A34: סיטי | B34: =COUNTIF('תוכניות בינוי'!$C$2:$C$41,"סיטי")
A35: פארק לכיש | B35: =COUNTIF('תוכניות בינוי'!$C$2:$C$41,"פארק לכיש")
A36: ריביירה | B36: =COUNTIF('תוכניות בינוי'!$C$2:$C$41,"ריביירה")
